Workbook

Sheet order
A1: order_id | B1: site | C1: region | D1: niche | E1: amount_usd | F1: date | G1: is_new_customer
A2: ORD341292 | B2: editgenius.net | C2: EU | D2: Programming | E2: 49.48 | F2: 45809 | G2: True
A3: ORD975467 | B3: paperwise.co | C3: US | D3: Presentation | E3: 79.34 | F3: 45809 | G3: True
A4: ORD426147 | B4: slidecraft.com | C4: US | D4: Academic | E4: 79.13 | F4: 45809 | G4: False
A5: ORD559398 | B5: paperwise.co | C5: AU | D5: Nursing | E5: 100.55 | F5: 45809 | G5: True
A6: ORD123005 | B6: paperwise.co | C6: AU | D6: Editing | E6: 89.63 | F6: 45809 | G6: True
A7: ORD444519 | B7: progassignments.io | C7: UK | D7: Academic | E7: 82.05 | F7: 45809 | G7: False
A8: ORD793169 | B8: typemaster.org | C8: US | D8: Programming | E8: 33.32 | F8: 45809 | G8: False
A9: ORD185569 | B9: leadacademica.co.uk | C9: CA | D9: Programming | E9: 102.49 | F9: 45809 | G9: False
A10: ORD745239 | B10: writemaster.co.uk | C10: US | D10: Nursing | E10: 95.74 | F10: 45809 | G10: False
A11: ORD864491 | B11: writemaster.co.uk | C11: US | D11: Nursing | E11: 84.28 | F11: 45810 | G11: False
A12: ORD299122 | B12: slidecraft.com | C12: CA | D12: Programming | E12: 35.92 | F12: 45810 | G12: True
A13: ORD704596 | B13: leadacademica.co.uk | C13: UK | D13: Editing | E13: 30.31 | F13: 45810 | G13: False
... A301: ORD332823 | B301: typemaster.org | C301: AU | D301: Editing | E301: 88.93 | F301: 45838 | G301: True

Sheet site_event_log
A1: site | B1: event | C1: user_id | D1: timestamp
A2: writemaster.co.uk | B2: cta_click | C2: user_2692 | D2: 45809
A3: writemaster.co.uk | B3: form_submit | C3: user_6882 | D3: 45809
A4: slidecraft.com | B4: cta_click | C4: user_8479 | D4: 45809
A5: progassignments.io | B5: cta_click | C5: user_1152 | D5: 45809
A6: slidecraft.com | B6: cta_click | C6: user_2195 | D6: 45809
A7: nursingessay.us | B7: form_submit | C7: user_6488 | D7: 45809
A8: typemaster.org | B8: checkout_initiate | C8: user_2989 | D8: 45809
A9: essayhubpro.net | B9: checkout_initiate | C9: user_4584 | D9: 45809
A10: slidecraft.com | B10: conversion | C10: user_1975 | D10: 45809
A11: typemaster.org | B11: form_submit | C11: user_5831 | D11: 45809
A12: writemaster.co.uk | B12: conversion | C12: user_7102 | D12: 45809
A13: paperwise.co | B13: form_submit | C13: user_5670 | D13: 45809
... A501: essayhubpro.net | B501: form_submit | C501: user_6860 | D501: 45838

Sheet site_mapping
A1: site | B1: region | C1: niche | D1: is_new_site
A2: essayhubpro.net | B2: UK | C2: Academic | D2: True
A3: typemaster.org | B3: AU | C3: Editing | D3: True
A4: slidecraft.com | B4: UK | C4: Presentation | D4: True
A5: progassignments.io | B5: US | C5: Editing | D5: False
A6: paperwise.co | B6: UK | C6: Nursing | D6: True
A7: nursingessay.us | B7: EU | C7: Editing | D7: False
A8: leadacademica.co.uk | B8: AU | C8: Presentation | D8: True
A9: writemaster.co.uk | B9: US | C9: Editing | D9: True
A10: editgenius.net | B10: EU | C10: Editing | D10: False

Sheet traffic_sources
A1: site | B1: source | C1: sessions | D1: date
A2: paperwise.co | B2: referral | C2: 91 | D2: 45809
A3: paperwise.co | B3: referral | C3: 128 | D3: 45809
A4: typemaster.org | B4: paid | C4: 39 | D4: 45809
A5: paperwise.co | B5: organic | C5: 103 | D5: 45809
A6: nursingessay.us | B6: paid | C6: 73 | D6: 45809
A7: paperwise.co | B7: featured_snippet | C7: 83 | D7: 45809
A8: essayhubpro.net | B8: people_also_ask | C8: 83 | D8: 45809
A9: essayhubpro.net | B9: people_also_ask | C9: 89 | D9: 45809
A10: editgenius.net | B10: referral | C10: 77 | D10: 45809
A11: nursingessay.us | B11: paid | C11: 67 | D11: 45810
A12: essayhubpro.net | B12: organic | C12: 104 | D12: 45810
A13: typemaster.org | B13: featured_snippet | C13: 70 | D13: 45810
... A401: essayhubpro.net | B401: paid | C401: 85 | D401: 45838

Sheet task_1
A1: 1. AI-джерела трафіку: останні 15 днів vs попередні 15 днів
A3: Дані охоплюють лише 30 днів (01/06/2025 - 30/06/2025). Як найближче наближення використано:
A4: • Попередній період: 01/06/2025 - 15/06/2025 (15 днів)
A5: • Останній період: 16/06/2025 - 30/06/2025 (15 днів)
A7: 1.1 Рейтинг сайтів за відносним приростом (від найбільшого до найменшого). Лише з джерел: ai_overview, ai_overview, people_also_ask.
A8: Site | B8: Попер. 15д | C8: Останні 15д | D8: Абс. приріст | E8: Відн. приріст % | F8: Рейтинг | G8: Кількість трафіку за 30д
A9: leadacademica.co.uk | B9: {=SUMPRODUCT((traffic_sources!$A$2:$A$401=$A9)*((traffic_sources!$B$2:$B$401="ai_overview")+(traffic_sources!$B$2:$B$401="featured_snippet")+(traffic_sources!$B$2:$B$401="people_also_ask"))*(traffic_sources!$D$2:$D$401>=45809)*(traffic_sources!$D$2:$D$401<=45823)*traffic_sources!$C$2:$C$401)} -> 716 | C9: {=SUMPRODUCT((traffic_sources!$A$2:$A$401=$A9)*((traffic_sources!$B$2:$B$401="ai_overview")+(traffic_sources!$B$2:$B$401="featured_snippet")+(traffic_sources!$B$2:$B$401="people_also_ask"))*(traffic_sources!$D$2:$D$401>=45824)*(traffic_sources!$D$2:$D$401<=45838)*traffic_sources!$C$2:$C$401)} -> 1966 | D9: =C9-B9 -> 1250 | E9: =IF(B9=0,IF(C9=0,0,1),(C9-B9)/B9) -> 1.7458101 | F9: 1 | G9: =B9+C9 -> 2682
A10: typemaster.org | B10: {=SUMPRODUCT((traffic_sources!$A$2:$A$401=$A10)*((traffic_sources!$B$2:$B$401="ai_overview")+(traffic_sources!$B$2:$B$401="featured_snippet")+(traffic_sources!$B$2:$B$401="people_also_ask"))*(traffic_sources!$D$2:$D$401>=45809)*(traffic_sources!$D$2:$D$401<=45823)*traffic_sources!$C$2:$C$401)} -> 494 | C10: {=SUMPRODUCT((traffic_sources!$A$2:$A$401=$A10)*((traffic_sources!$B$2:$B$401="ai_overview")+(traffic_sources!$B$2:$B$401="featured_snippet")+(traffic_sources!$B$2:$B$401="people_also_ask"))*(traffic_sources!$D$2:$D$401>=45824)*(traffic_sources!$D$2:$D$401<=45838)*traffic_sources!$C$2:$C$401)} -> 1117 | D10: =C10-B10 -> 623 | E10: =IF(B10=0,IF(C10=0,0,1),(C10-B10)/B10) -> 1.2611336 | F10: 2 | G10: =B10+C10 -> 1611
A11: writemaster.co.uk | B11: {=SUMPRODUCT((traffic_sources!$A$2:$A$401=$A11)*((traffic_sources!$B$2:$B$401="ai_overview")+(traffic_sources!$B$2:$B$401="featured_snippet")+(traffic_sources!$B$2:$B$401="people_also_ask"))*(traffic_sources!$D$2:$D$401>=45809)*(traffic_sources!$D$2:$D$401<=45823)*traffic_sources!$C$2:$C$401)} -> 611 | C11: {=SUMPRODUCT((traffic_sources!$A$2:$A$401=$A11)*((traffic_sources!$B$2:$B$401="ai_overview")+(traffic_sources!$B$2:$B$401="featured_snippet")+(traffic_sources!$B$2:$B$401="people_also_ask"))*(traffic_sources!$D$2:$D$401>=45824)*(traffic_sources!$D$2:$D$401<=45838)*traffic_sources!$C$2:$C$401)} -> 667 | D11: =C11-B11 -> 56 | E11: =IF(B11=0,IF(C11=0,0,1),(C11-B11)/B11) -> 0.091653028 | F11: 3 | G11: =B11+C11 -> 1278
A12: nursingessay.us | B12: {=SUMPRODUCT((traffic_sources!$A$2:$A$401=$A12)*((traffic_sources!$B$2:$B$401="ai_overview")+(traffic_sources!$B$2:$B$401="featured_snippet")+(traffic_sources!$B$2:$B$401="people_also_ask"))*(traffic_sources!$D$2:$D$401>=45809)*(traffic_sources!$D$2:$D$401<=45823)*traffic_sources!$C$2:$C$401)} -> 1154 | C12: {=SUMPRODUCT((traffic_sources!$A$2:$A$401=$A12)*((traffic_sources!$B$2:$B$401="ai_overview")+(traffic_sources!$B$2:$B$401="featured_snippet")+(traffic_sources!$B$2:$B$401="people_also_ask"))*(traffic_sources!$D$2:$D$401>=45824)*(traffic_sources!$D$2:$D$401<=45838)*traffic_sources!$C$2:$C$401)} -> 1087 | D12: =C12-B12 -> -67 | E12: =IF(B12=0,IF(C12=0,0,1),(C12-B12)/B12) -> -0.058058925 | F12: 4 | G12: =B12+C12 -> 2241
A13: slidecraft.com | B13: {=SUMPRODUCT((traffic_sources!$A$2:$A$401=$A13)*((traffic_sources!$B$2:$B$401="ai_overview")+(traffic_sources!$B$2:$B$401="featured_snippet")+(traffic_sources!$B$2:$B$401="people_also_ask"))*(traffic_sources!$D$2:$D$401>=45809)*(traffic_sources!$D$2:$D$401<=45823)*traffic_sources!$C$2:$C$401)} -> 1264 | C13: {=SUMPRODUCT((traffic_sources!$A$2:$A$401=$A13)*((traffic_sources!$B$2:$B$401="ai_overview")+(traffic_sources!$B$2:$B$401="featured_snippet")+(traffic_sources!$B$2:$B$401="people_also_ask"))*(traffic_sources!$D$2:$D$401>=45824)*(traffic_sources!$D$2:$D$401<=45838)*traffic_sources!$C$2:$C$401)} -> 1104 | D13: =C13-B13 -> -160 | E13: =IF(B13=0,IF(C13=0,0,1),(C13-B13)/B13) -> -0.12658228 | F13: 5 | G13: =B13+C13 -> 2368
A14: editgenius.net | B14: {=SUMPRODUCT((traffic_sources!$A$2:$A$401=$A14)*((traffic_sources!$B$2:$B$401="ai_overview")+(traffic_sources!$B$2:$B$401="featured_snippet")+(traffic_sources!$B$2:$B$401="people_also_ask"))*(traffic_sources!$D$2:$D$401>=45809)*(traffic_sources!$D$2:$D$401<=45823)*traffic_sources!$C$2:$C$401)} -> 571 | C14: {=SUMPRODUCT((traffic_sources!$A$2:$A$401=$A14)*((traffic_sources!$B$2:$B$401="ai_overview")+(traffic_sources!$B$2:$B$401="featured_snippet")+(traffic_sources!$B$2:$B$401="people_also_ask"))*(traffic_sources!$D$2:$D$401>=45824)*(traffic_sources!$D$2:$D$401<=45838)*traffic_sources!$C$2:$C$401)} -> 477 | D14: =C14-B14 -> -94 | E14: =IF(B14=0,IF(C14=0,0,1),(C14-B14)/B14) -> -0.16462347 | F14: 6 | G14: =B14+C14 -> 1048
A15: paperwise.co | B15: {=SUMPRODUCT((traffic_sources!$A$2:$A$401=$A15)*((traffic_sources!$B$2:$B$401="ai_overview")+(traffic_sources!$B$2:$B$401="featured_snippet")+(traffic_sources!$B$2:$B$401="people_also_ask"))*(traffic_sources!$D$2:$D$401>=45809)*(traffic_sources!$D$2:$D$401<=45823)*traffic_sources!$C$2:$C$401)} -> 1210 | C15: {=SUMPRODUCT((traffic_sources!$A$2:$A$401=$A15)*((traffic_sources!$B$2:$B$401="ai_overview")+(traffic_sources!$B$2:$B$401="featured_snippet")+(traffic_sources!$B$2:$B$401="people_also_ask"))*(traffic_sources!$D$2:$D$401>=45824)*(traffic_sources!$D$2:$D$401<=45838)*traffic_sources!$C$2:$C$401)} -> 921 | D15: =C15-B15 -> -289 | E15: =IF(B15=0,IF(C15=0,0,1),(C15-B15)/B15) -> -0.23884298 | F15: 7 | G15: =B15+C15 -> 2131
A16: essayhubpro.net | B16: {=SUMPRODUCT((traffic_sources!$A$2:$A$401=$A16)*((traffic_sources!$B$2:$B$401="ai_overview")+(traffic_sources!$B$2:$B$401="featured_snippet")+(traffic_sources!$B$2:$B$401="people_also_ask"))*(traffic_sources!$D$2:$D$401>=45809)*(traffic_sources!$D$2:$D$401<=45823)*traffic_sources!$C$2:$C$401)} -> 1357 | C16: {=SUMPRODUCT((traffic_sources!$A$2:$A$401=$A16)*((traffic_sources!$B$2:$B$401="ai_overview")+(traffic_sources!$B$2:$B$401="featured_snippet")+(traffic_sources!$B$2:$B$401="people_also_ask"))*(traffic_sources!$D$2:$D$401>=45824)*(traffic_sources!$D$2:$D$401<=45838)*traffic_sources!$C$2:$C$401)} -> 985 | D16: =C16-B16 -> -372 | E16: =IF(B16=0,IF(C16=0,0,1),(C16-B16)/B16) -> -0.27413412 | F16: 8 | G16: =B16+C16 -> 2342
A17: progassignments.io | B17: {=SUMPRODUCT((traffic_sources!$A$2:$A$401=$A17)*((traffic_sources!$B$2:$B$401="ai_overview")+(traffic_sources!$B$2:$B$401="featured_snippet")+(traffic_sources!$B$2:$B$401="people_also_ask"))*(traffic_sources!$D$2:$D$401>=45809)*(traffic_sources!$D$2:$D$401<=45823)*traffic_sources!$C$2:$C$401)} -> 1061 | C17: {=SUMPRODUCT((traffic_sources!$A$2:$A$401=$A17)*((traffic_sources!$B$2:$B$401="ai_overview")+(traffic_sources!$B$2:$B$401="featured_snippet")+(traffic_sources!$B$2:$B$401="people_also_ask"))*(traffic_sources!$D$2:$D$401>=45824)*(traffic_sources!$D$2:$D$401<=45838)*traffic_sources!$C$2:$C$401)} -> 660 | D17: =C17-B17 -> -401 | E17: =IF(B17=0,IF(C17=0,0,1),(C17-B17)/B17) -> -0.37794533 | F17: 9 | G17: =B17+C17 -> 1721
A19: 1.2 Розбивка по кожному AI-джерелу окремо
B20: ai_overview | E20: featured_snippet | H20: people_also_ask
A21: Site | B21: Попер. 15д | C21: Останні 15д | D21: Приріст % | E21: Попер. 15д* | F21: Останні 15д* | G21: Приріст %* | H21: Попер. 15д** | I21: Останні 15д** | J21: Приріст %**
A22: leadacademica.co.uk | B22: =SUMIFS(traffic_sources!$C$2:$C$401,traffic_sources!$A$2:$A$401,$A22,traffic_sources!$B$2:$B$401,"ai_overview",traffic_sources!$D$2:$D$401,">=45809",traffic_sources!$D$2:$D$401,"<=45823") -> 114 | C22: =SUMIFS(traffic_sources!$C$2:$C$401,traffic_sources!$A$2:$A$401,$A22,traffic_sources!$B$2:$B$401,"ai_overview",traffic_sources!$D$2:$D$401,">=45824",traffic_sources!$D$2:$D$401,"<=45838") -> 705 | D22: =IF(B22=0,IF(C22=0,0,1),(C22-B22)/B22) -> 5.1842105 | E22: =SUMIFS(traffic_sources!$C$2:$C$401,traffic_sources!$A$2:$A$401,$A22,traffic_sources!$B$2:$B$401,"featured_snippet",traffic_sources!$D$2:$D$401,">=45809",traffic_sources!$D$2:$D$401,"<=45823") -> 213 | F22: =SUMIFS(traffic_sources!$C$2:$C$401,traffic_sources!$A$2:$A$401,$A22,traffic_sources!$B$2:$B$401,"featured_snippet",traffic_sources!$D$2:$D$401,">=45824",traffic_sources!$D$2:$D$401,"<=45838") -> 630 | G22: =IF(E22=0,IF(F22=0,0,1),(F22-E22)/E22) -> 1.9577465 | H22: =SUMIFS(traffic_sources!$C$2:$C$401,traffic_sources!$A$2:$A$401,$A22,traffic_sources!$B$2:$B$401,"people_also_ask",traffic_sources!$D$2:$D$401,">=45809",traffic_sources!$D$2:$D$401,"<=45823") -> 389 | I22: =SUMIFS(traffic_sources!$C$2:$C$401,traffic_sources!$A$2:$A$401,$A22,traffic_sources!$B$2:$B$401,"people_also_ask",traffic_sources!$D$2:$D$401,">=45824",traffic_sources!$D$2:$D$401,"<=45838") -> 631 | J22: =IF(H22=0,IF(I22=0,0,1),(I22-H22)/H22) -> 0.62210797
A23: typemaster.org | B23: =SUMIFS(traffic_sources!$C$2:$C$401,traffic_sources!$A$2:$A$401,$A23,traffic_sources!$B$2:$B$401,"ai_overview",traffic_sources!$D$2:$D$401,">=45809",traffic_sources!$D$2:$D$401,"<=45823") -> 424 | C23: =SUMIFS(traffic_sources!$C$2:$C$401,traffic_sources!$A$2:$A$401,$A23,traffic_sources!$B$2:$B$401,"ai_overview",traffic_sources!$D$2:$D$401,">=45824",traffic_sources!$D$2:$D$401,"<=45838") -> 488 | D23: =IF(B23=0,IF(C23=0,0,1),(C23-B23)/B23) -> 0.1509434 | E23: =SUMIFS(traffic_sources!$C$2:$C$401,traffic_sources!$A$2:$A$401,$A23,traffic_sources!$B$2:$B$401,"featured_snippet",traffic_sources!$D$2:$D$401,">=45809",traffic_sources!$D$2:$D$401,"<=45823") -> 70 | F23: =SUMIFS(traffic_sources!$C$2:$C$401,traffic_sources!$A$2:$A$401,$A23,traffic_sources!$B$2:$B$401,"featured_snippet",traffic_sources!$D$2:$D$401,">=45824",traffic_sources!$D$2:$D$401,"<=45838") -> 302 | G23: =IF(E23=0,IF(F23=0,0,1),(F23-E23)/E23) -> 3.3142857 | H23: =SUMIFS(traffic_sources!$C$2:$C$401,traffic_sources!$A$2:$A$401,$A23,traffic_sources!$B$2:$B$401,"people_also_ask",traffic_sources!$D$2:$D$401,">=45809",traffic_sources!$D$2:$D$401,"<=45823") -> 0 | I23: =SUMIFS(traffic_sources!$C$2:$C$401,traffic_sources!$A$2:$A$401,$A23,traffic_sources!$B$2:$B$401,"people_also_ask",traffic_sources!$D$2:$D$401,">=45824",traffic_sources!$D$2:$D$401,"<=45838") -> 327 | J23: =IF(H23=0,IF(I23=0,0,1),(I23-H23)/H23) -> 1
A24: writemaster.co.uk | B24: =SUMIFS(traffic_sources!$C$2:$C$401,traffic_sources!$A$2:$A$401,$A24,traffic_sources!$B$2:$B$401,"ai_overview",traffic_sources!$D$2:$D$401,">=45809",traffic_sources!$D$2:$D$401,"<=45823") -> 351 | C24: =SUMIFS(traffic_sources!$C$2:$C$401,traffic_sources!$A$2:$A$401,$A24,traffic_sources!$B$2:$B$401,"ai_overview",traffic_sources!$D$2:$D$401,">=45824",traffic_sources!$D$2:$D$401,"<=45838") -> 76 | D24: =IF(B24=0,IF(C24=0,0,1),(C24-B24)/B24) -> -0.78347578 | E24: =SUMIFS(traffic_sources!$C$2:$C$401,traffic_sources!$A$2:$A$401,$A24,traffic_sources!$B$2:$B$401,"featured_snippet",traffic_sources!$D$2:$D$401,">=45809",traffic_sources!$D$2:$D$401,"<=45823") -> 34 | F24: =SUMIFS(traffic_sources!$C$2:$C$401,traffic_sources!$A$2:$A$401,$A24,traffic_sources!$B$2:$B$401,"featured_snippet",traffic_sources!$D$2:$D$401,">=45824",traffic_sources!$D$2:$D$401,"<=45838") -> 435 | G24: =IF(E24=0,IF(F24=0,0,1),(F24-E24)/E24) -> 11.794118 | H24: =SUMIFS(traffic_sources!$C$2:$C$401,traffic_sources!$A$2:$A$401,$A24,traffic_sources!$B$2:$B$401,"people_also_ask",traffic_sources!$D$2:$D$401,">=45809",traffic_sources!$D$2:$D$401,"<=45823") -> 226 | I24: =SUMIFS(traffic_sources!$C$2:$C$401,traffic_sources!$A$2:$A$401,$A24,traffic_sources!$B$2:$B$401,"people_also_ask",traffic_sources!$D$2:$D$401,">=45824",traffic_sources!$D$2:$D$401,"<=45838") -> 156 | J24: =IF(H24=0,IF(I24=0,0,1),(I24-H24)/H24) -> -0.30973451
A25: nursingessay.us | B25: =SUMIFS(traffic_sources!$C$2:$C$401,traffic_sources!$A$2:$A$401,$A25,traffic_sources!$B$2:$B$401,"ai_overview",traffic_sources!$D$2:$D$401,">=45809",traffic_sources!$D$2:$D$401,"<=45823") -> 586 | C25: =SUMIFS(traffic_sources!$C$2:$C$401,traffic_sources!$A$2:$A$401,$A25,traffic_sources!$B$2:$B$401,"ai_overview",traffic_sources!$D$2:$D$401,">=45824",traffic_sources!$D$2:$D$401,"<=45838") -> 303 | D25: =IF(B25=0,IF(C25=0,0,1),(C25-B25)/B25) -> -0.48293515 | E25: =SUMIFS(traffic_sources!$C$2:$C$401,traffic_sources!$A$2:$A$401,$A25,traffic_sources!$B$2:$B$401,"featured_snippet",traffic_sources!$D$2:$D$401,">=45809",traffic_sources!$D$2:$D$401,"<=45823") -> 458 | F25: =SUMIFS(traffic_sources!$C$2:$C$401,traffic_sources!$A$2:$A$401,$A25,traffic_sources!$B$2:$B$401,"featured_snippet",traffic_sources!$D$2:$D$401,">=45824",traffic_sources!$D$2:$D$401,"<=45838") -> 434 | G25: =IF(E25=0,IF(F25=0,0,1),(F25-E25)/E25) -> -0.052401747 | H25: =SUMIFS(traffic_sources!$C$2:$C$401,traffic_sources!$A$2:$A$401,$A25,traffic_sources!$B$2:$B$401,"people_also_ask",traffic_sources!$D$2:$D$401,">=45809",traffic_sources!$D$2:$D$401,"<=45823") -> 110 | I25: =SUMIFS(traffic_sources!$C$2:$C$401,traffic_sources!$A$2:$A$401,$A25,traffic_sources!$B$2:$B$401,"people_also_ask",traffic_sources!$D$2:$D$401,">=45824",traffic_sources!$D$2:$D$401,"<=45838") -> 350 | J25: =IF(H25=0,IF(I25=0,0,1),(I25-H25)/H25) -> 2.1818182
A26: slidecraft.com | B26: =SUMIFS(traffic_sources!$C$2:$C$401,traffic_sources!$A$2:$A$401,$A26,traffic_sources!$B$2:$B$401,"ai_overview",traffic_sources!$D$2:$D$401,">=45809",traffic_sources!$D$2:$D$401,"<=45823") -> 322 | C26: =SUMIFS(traffic_sources!$C$2:$C$401,traffic_sources!$A$2:$A$401,$A26,traffic_sources!$B$2:$B$401,"ai_overview",traffic_sources!$D$2:$D$401,">=45824",traffic_sources!$D$2:$D$401,"<=45838") -> 176 | D26: =IF(B26=0,IF(C26=0,0,1),(C26-B26)/B26) -> -0.45341615 | E26: =SUMIFS(traffic_sources!$C$2:$C$401,traffic_sources!$A$2:$A$401,$A26,traffic_sources!$B$2:$B$401,"featured_snippet",traffic_sources!$D$2:$D$401,">=45809",traffic_sources!$D$2:$D$401,"<=45823") -> 191 | F26: =SUMIFS(traffic_sources!$C$2:$C$401,traffic_sources!$A$2:$A$401,$A26,traffic_sources!$B$2:$B$401,"featured_snippet",traffic_sources!$D$2:$D$401,">=45824",traffic_sources!$D$2:$D$401,"<=45838") -> 416 | G26: =IF(E26=0,IF(F26=0,0,1),(F26-E26)/E26) -> 1.1780105 | H26: =SUMIFS(traffic_sources!$C$2:$C$401,traffic_sources!$A$2:$A$401,$A26,traffic_sources!$B$2:$B$401,"people_also_ask",traffic_sources!$D$2:$D$401,">=45809",traffic_sources!$D$2:$D$401,"<=45823") -> 751 | I26: =SUMIFS(traffic_sources!$C$2:$C$401,traffic_sources!$A$2:$A$401,$A26,traffic_sources!$B$2:$B$401,"people_also_ask",traffic_sources!$D$2:$D$401,">=45824",traffic_sources!$D$2:$D$401,"<=45838") -> 512 | J26: =IF(H26=0,IF(I26=0,0,1),(I26-H26)/H26) -> -0.31824234
A27: editgenius.net | B27: =SUMIFS(traffic_sources!$C$2:$C$401,traffic_sources!$A$2:$A$401,$A27,traffic_sources!$B$2:$B$401,"ai_overview",traffic_sources!$D$2:$D$401,">=45809",traffic_sources!$D$2:$D$401,"<=45823") -> 0 | C27: =SUMIFS(traffic_sources!$C$2:$C$401,traffic_sources!$A$2:$A$401,$A27,traffic_sources!$B$2:$B$401,"ai_overview",traffic_sources!$D$2:$D$401,">=45824",traffic_sources!$D$2:$D$401,"<=45838") -> 0 | D27: =IF(B27=0,IF(C27=0,0,1),(C27-B27)/B27) -> 0 | E27: =SUMIFS(traffic_sources!$C$2:$C$401,traffic_sources!$A$2:$A$401,$A27,traffic_sources!$B$2:$B$401,"featured_snippet",traffic_sources!$D$2:$D$401,">=45809",traffic_sources!$D$2:$D$401,"<=45823") -> 571 | F27: =SUMIFS(traffic_sources!$C$2:$C$401,traffic_sources!$A$2:$A$401,$A27,traffic_sources!$B$2:$B$401,"featured_snippet",traffic_sources!$D$2:$D$401,">=45824",traffic_sources!$D$2:$D$401,"<=45838") -> 124 | G27: =IF(E27=0,IF(F27=0,0,1),(F27-E27)/E27) -> -0.78283713 | H27: =SUMIFS(traffic_sources!$C$2:$C$401,traffic_sources!$A$2:$A$401,$A27,traffic_sources!$B$2:$B$401,"people_also_ask",traffic_sources!$D$2:$D$401,">=45809",traffic_sources!$D$2:$D$401,"<=45823") -> 0 | I27: =SUMIFS(traffic_sources!$C$2:$C$401,traffic_sources!$A$2:$A$401,$A27,traffic_sources!$B$2:$B$401,"people_also_ask",traffic_sources!$D$2:$D$401,">=45824",traffic_sources!$D$2:$D$401,"<=45838") -> 353 | J27: =IF(H27=0,IF(I27=0,0,1),(I27-H27)/H27) -> 1
A28: paperwise.co | B28: =SUMIFS(traffic_sources!$C$2:$C$401,traffic_sources!$A$2:$A$401,$A28,traffic_sources!$B$2:$B$401,"ai_overview",traffic_sources!$D$2:$D$401,">=45809",traffic_sources!$D$2:$D$401,"<=45823") -> 214 | C28: =SUMIFS(traffic_sources!$C$2:$C$401,traffic_sources!$A$2:$A$401,$A28,traffic_sources!$B$2:$B$401,"ai_overview",traffic_sources!$D$2:$D$401,">=45824",traffic_sources!$D$2:$D$401,"<=45838") -> 389 | D28: =IF(B28=0,IF(C28=0,0,1),(C28-B28)/B28) -> 0.81775701 | E28: =SUMIFS(traffic_sources!$C$2:$C$401,traffic_sources!$A$2:$A$401,$A28,traffic_sources!$B$2:$B$401,"featured_snippet",traffic_sources!$D$2:$D$401,">=45809",traffic_sources!$D$2:$D$401,"<=45823") -> 682 | F28: =SUMIFS(traffic_sources!$C$2:$C$401,traffic_sources!$A$2:$A$401,$A28,traffic_sources!$B$2:$B$401,"featured_snippet",traffic_sources!$D$2:$D$401,">=45824",traffic_sources!$D$2:$D$401,"<=45838") -> 441 | G28: =IF(E28=0,IF(F28=0,0,1),(F28-E28)/E28) -> -0.35337243 | H28: =SUMIFS(traffic_sources!$C$2:$C$401,traffic_sources!$A$2:$A$401,$A28,traffic_sources!$B$2:$B$401,"people_also_ask",traffic_sources!$D$2:$D$401,">=45809",traffic_sources!$D$2:$D$401,"<=45823") -> 314 | I28: =SUMIFS(traffic_sources!$C$2:$C$401,traffic_sources!$A$2:$A$401,$A28,traffic_sources!$B$2:$B$401,"people_also_ask",traffic_sources!$D$2:$D$401,">=45824",traffic_sources!$D$2:$D$401,"<=45838") -> 91 | J28: =IF(H28=0,IF(I28=0,0,1),(I28-H28)/H28) -> -0.71019108
A29: essayhubpro.net | B29: =SUMIFS(traffic_sources!$C$2:$C$401,traffic_sources!$A$2:$A$401,$A29,traffic_sources!$B$2:$B$401,"ai_overview",traffic_sources!$D$2:$D$401,">=45809",traffic_sources!$D$2:$D$401,"<=45823") -> 325 | C29: =SUMIFS(traffic_sources!$C$2:$C$401,traffic_sources!$A$2:$A$401,$A29,traffic_sources!$B$2:$B$401,"ai_overview",traffic_sources!$D$2:$D$401,">=45824",traffic_sources!$D$2:$D$401,"<=45838") -> 379 | D29: =IF(B29=0,IF(C29=0,0,1),(C29-B29)/B29) -> 0.16615385 | E29: =SUMIFS(traffic_sources!$C$2:$C$401,traffic_sources!$A$2:$A$401,$A29,traffic_sources!$B$2:$B$401,"featured_snippet",traffic_sources!$D$2:$D$401,">=45809",traffic_sources!$D$2:$D$401,"<=45823") -> 524 | F29: =SUMIFS(traffic_sources!$C$2:$C$401,traffic_sources!$A$2:$A$401,$A29,traffic_sources!$B$2:$B$401,"featured_snippet",traffic_sources!$D$2:$D$401,">=45824",traffic_sources!$D$2:$D$401,"<=45838") -> 233 | G29: =IF(E29=0,IF(F29=0,0,1),(F29-E29)/E29) -> -0.55534351 | H29: =SUMIFS(traffic_sources!$C$2:$C$401,traffic_sources!$A$2:$A$401,$A29,traffic_sources!$B$2:$B$401,"people_also_ask",traffic_sources!$D$2:$D$401,">=45809",traffic_sources!$D$2:$D$401,"<=45823") -> 508 | I29: =SUMIFS(traffic_sources!$C$2:$C$401,traffic_sources!$A$2:$A$401,$A29,traffic_sources!$B$2:$B$401,"people_also_ask",traffic_sources!$D$2:$D$401,">=45824",traffic_sources!$D$2:$D$401,"<=45838") -> 373 | J29: =IF(H29=0,IF(I29=0,0,1),(I29-H29)/H29) -> -0.26574803
A30: progassignments.io | B30: =SUMIFS(traffic_sources!$C$2:$C$401,traffic_sources!$A$2:$A$401,$A30,traffic_sources!$B$2:$B$401,"ai_overview",traffic_sources!$D$2:$D$401,">=45809",traffic_sources!$D$2:$D$401,"<=45823") -> 353 | C30: =SUMIFS(traffic_sources!$C$2:$C$401,traffic_sources!$A$2:$A$401,$A30,traffic_sources!$B$2:$B$401,"ai_overview",traffic_sources!$D$2:$D$401,">=45824",traffic_sources!$D$2:$D$401,"<=45838") -> 63 | D30: =IF(B30=0,IF(C30=0,0,1),(C30-B30)/B30) -> -0.82152975 | E30: =SUMIFS(traffic_sources!$C$2:$C$401,traffic_sources!$A$2:$A$401,$A30,traffic_sources!$B$2:$B$401,"featured_snippet",traffic_sources!$D$2:$D$401,">=45809",traffic_sources!$D$2:$D$401,"<=45823") -> 363 | F30: =SUMIFS(traffic_sources!$C$2:$C$401,traffic_sources!$A$2:$A$401,$A30,traffic_sources!$B$2:$B$401,"featured_snippet",traffic_sources!$D$2:$D$401,">=45824",traffic_sources!$D$2:$D$401,"<=45838") -> 250 | G30: =IF(E30=0,IF(F30=0,0,1),(F30-E30)/E30) -> -0.31129477 | H30: =SUMIFS(traffic_sources!$C$2:$C$401,traffic_sources!$A$2:$A$401,$A30,traffic_sources!$B$2:$B$401,"people_also_ask",traffic_sources!$D$2:$D$401,">=45809",traffic_sources!$D$2:$D$401,"<=45823") -> 345 | I30: =SUMIFS(traffic_sources!$C$2:$C$401,traffic_sources!$A$2:$A$401,$A30,traffic_sources!$B$2:$B$401,"people_also_ask",traffic_sources!$D$2:$D$401,">=45824",traffic_sources!$D$2:$D$401,"<=45838") -> 347 | J30: =IF(H30=0,IF(I30=0,0,1),(I30-H30)/H30) -> 0.0057971014
A32: 1.3 Кумулятивний приріст AI-трафіку (ai_overview + featured_snippet + people_also_ask)
A33: Дата | B33: AI-трафік (день) | C33: Кумулятивно
A34: 45809 | B34: {=SUMPRODUCT(((traffic_sources!$B$2:$B$401="ai_overview")+(traffic_sources!$B$2:$B$401="featured_snippet")+(traffic_sources!$B$2:$B$401="people_also_ask"))*(traffic_sources!$D$2:$D$401=$A34)*traffic_sources!$C$2:$C$401)} -> 255 | C34: =B34 -> 255
A35: 45810 | B35: {=SUMPRODUCT(((traffic_sources!$B$2:$B$401="ai_overview")+(traffic_sources!$B$2:$B$401="featured_snippet")+(traffic_sources!$B$2:$B$401="people_also_ask"))*(traffic_sources!$D$2:$D$401=$A35)*traffic_sources!$C$2:$C$401)} -> 275 | C35: =C34+B35 -> 530
A36: 45811 | B36: {=SUMPRODUCT(((traffic_sources!$B$2:$B$401="ai_overview")+(traffic_sources!$B$2:$B$401="featured_snippet")+(traffic_sources!$B$2:$B$401="people_also_ask"))*(traffic_sources!$D$2:$D$401=$A36)*traffic_sources!$C$2:$C$401)} -> 902 | C36: =C35+B36 -> 1432
A37: 45812 | B37: {=SUMPRODUCT(((traffic_sources!$B$2:$B$401="ai_overview")+(traffic_sources!$B$2:$B$401="featured_snippet")+(traffic_sources!$B$2:$B$401="people_also_ask"))*(traffic_sources!$D$2:$D$401=$A37)*traffic_sources!$C$2:$C$401)} -> 735 | C37: =C36+B37 -> 2167
A38: 45813 | B38: {=SUMPRODUCT(((traffic_sources!$B$2:$B$401="ai_overview")+(traffic_sources!$B$2:$B$401="featured_snippet")+(traffic_sources!$B$2:$B$401="people_also_ask"))*(traffic_sources!$D$2:$D$401=$A38)*traffic_sources!$C$2:$C$401)} -> 1004 | C38: =C37+B38 -> 3171
A39: 45814 | B39: {=SUMPRODUCT(((traffic_sources!$B$2:$B$401="ai_overview")+(traffic_sources!$B$2:$B$401="featured_snippet")+(traffic_sources!$B$2:$B$401="people_also_ask"))*(traffic_sources!$D$2:$D$401=$A39)*traffic_sources!$C$2:$C$401)} -> 220 | C39: =C38+B39 -> 3391
A40: 45815 | B40: {=SUMPRODUCT(((traffic_sources!$B$2:$B$401="ai_overview")+(traffic_sources!$B$2:$B$401="featured_snippet")+(traffic_sources!$B$2:$B$401="people_also_ask"))*(traffic_sources!$D$2:$D$401=$A40)*traffic_sources!$C$2:$C$401)} -> 320 | C40: =C39+B40 -> 3711
A41: 45816 | B41: {=SUMPRODUCT(((traffic_sources!$B$2:$B$401="ai_overview")+(traffic_sources!$B$2:$B$401="featured_snippet")+(traffic_sources!$B$2:$B$401="people_also_ask"))*(traffic_sources!$D$2:$D$401=$A41)*traffic_sources!$C$2:$C$401)} -> 631 | C41: =C40+B41 -> 4342
A42: 45817 | B42: {=SUMPRODUCT(((traffic_sources!$B$2:$B$401="ai_overview")+(traffic_sources!$B$2:$B$401="featured_snippet")+(traffic_sources!$B$2:$B$401="people_also_ask"))*(traffic_sources!$D$2:$D$401=$A42)*traffic_sources!$C$2:$C$401)} -> 236 | C42: =C41+B42 -> 4578
A43: 45818 | B43: {=SUMPRODUCT(((traffic_sources!$B$2:$B$401="ai_overview")+(traffic_sources!$B$2:$B$401="featured_snippet")+(traffic_sources!$B$2:$B$401="people_also_ask"))*(traffic_sources!$D$2:$D$401=$A43)*traffic_sources!$C$2:$C$401)} -> 566 | C43: =C42+B43 -> 5144
A44: 45819 | B44: {=SUMPRODUCT(((traffic_sources!$B$2:$B$401="ai_overview")+(traffic_sources!$B$2:$B$401="featured_snippet")+(traffic_sources!$B$2:$B$401="people_also_ask"))*(traffic_sources!$D$2:$D$401=$A44)*traffic_sources!$C$2:$C$401)} -> 577 | C44: =C43+B44 -> 5721
...

Sheet task_2
A1: 2. Продажі: кількість і сума по сайтах та регіонах
A3: Правило: для essayhubpro.net, paperwise.co, editgenius.net у регіоні US враховуються лише нові клієнти (is_new_customer = TRUE).
A5: 2.1 Підсумок по сайтах | E5: 2.2 Підсумок по регіонах | I5: 2.4 Дохід по днях
A6: Site | B6: Кількість замовлень | C6: Сума ($) | E6: Region | F6: Кількість | G6: Сума ($) | I6: Дата | J6: Сума ($)
A7: paperwise.co | B7: {=SUMPRODUCT((order!$B$2:$B$301=$A7)*1)-SUMPRODUCT((order!$B$2:$B$301=$A7)*(((order!$B$2:$B$301="essayhubpro.net")+(order!$B$2:$B$301="paperwise.co")+(order!$B$2:$B$301="editgenius.net"))*(order!$C$2:$C$301="US")*(order!$G$2:$G$301="False")))} -> 35 | C7: {=SUMPRODUCT((order!$B$2:$B$301=$A7)*order!$E$2:$E$301)-SUMPRODUCT((order!$B$2:$B$301=$A7)*(((order!$B$2:$B$301="essayhubpro.net")+(order!$B$2:$B$301="paperwise.co")+(order!$B$2:$B$301="editgenius.net"))*(order!$C$2:$C$301="US")*(order!$G$2:$G$301="False"))*order!$E$2:$E$301)} -> 2964.16 | E7: US | F7: {=SUMPRODUCT((order!$C$2:$C$301=$E7)*1)-IF($E7="US",SUMPRODUCT((((order!$B$2:$B$301="essayhubpro.net")+(order!$B$2:$B$301="paperwise.co")+(order!$B$2:$B$301="editgenius.net"))*(order!$C$2:$C$301="US")*(order!$G$2:$G$301="False"))),0)} -> 50 | G7: {=SUMPRODUCT((order!$C$2:$C$301=$E7)*order!$E$2:$E$301)-IF($E7="US",SUMPRODUCT((((order!$B$2:$B$301="essayhubpro.net")+(order!$B$2:$B$301="paperwise.co")+(order!$B$2:$B$301="editgenius.net"))*(order!$C$2:$C$301="US")*(order!$G$2:$G$301="False"))*order!$E$2:$E$301),0)} -> 3973.32 | I7: 45809 | J7: {=SUMPRODUCT((order!$F$2:$F$301=I7)*order!$E$2:$E$301)-SUMPRODUCT((order!$F$2:$F$301=I7)*(((order!$B$2:$B$301="essayhubpro.net")+(order!$B$2:$B$301="paperwise.co")+(order!$B$2:$B$301="editgenius.net"))*(order!$C$2:$C$301="US")*(order!$G$2:$G$301="False"))*order!$E$2:$E$301)} -> 711.73
A8: typemaster.org | B8: {=SUMPRODUCT((order!$B$2:$B$301=$A8)*1)-SUMPRODUCT((order!$B$2:$B$301=$A8)*(((order!$B$2:$B$301="essayhubpro.net")+(order!$B$2:$B$301="paperwise.co")+(order!$B$2:$B$301="editgenius.net"))*(order!$C$2:$C$301="US")*(order!$G$2:$G$301="False")))} -> 40 | C8: {=SUMPRODUCT((order!$B$2:$B$301=$A8)*order!$E$2:$E$301)-SUMPRODUCT((order!$B$2:$B$301=$A8)*(((order!$B$2:$B$301="essayhubpro.net")+(order!$B$2:$B$301="paperwise.co")+(order!$B$2:$B$301="editgenius.net"))*(order!$C$2:$C$301="US")*(order!$G$2:$G$301="False"))*order!$E$2:$E$301)} -> 3472.86 | E8: EU | F8: {=SUMPRODUCT((order!$C$2:$C$301=$E8)*1)-IF($E8="US",SUMPRODUCT((((order!$B$2:$B$301="essayhubpro.net")+(order!$B$2:$B$301="paperwise.co")+(order!$B$2:$B$301="editgenius.net"))*(order!$C$2:$C$301="US")*(order!$G$2:$G$301="False"))),0)} -> 59 | G8: {=SUMPRODUCT((order!$C$2:$C$301=$E8)*order!$E$2:$E$301)-IF($E8="US",SUMPRODUCT((((order!$B$2:$B$301="essayhubpro.net")+(order!$B$2:$B$301="paperwise.co")+(order!$B$2:$B$301="editgenius.net"))*(order!$C$2:$C$301="US")*(order!$G$2:$G$301="False"))*order!$E$2:$E$301),0)} -> 4549.48 | I8: 45810 | J8: {=SUMPRODUCT((order!$F$2:$F$301=I8)*order!$E$2:$E$301)-SUMPRODUCT((order!$F$2:$F$301=I8)*(((order!$B$2:$B$301="essayhubpro.net")+(order!$B$2:$B$301="paperwise.co")+(order!$B$2:$B$301="editgenius.net"))*(order!$C$2:$C$301="US")*(order!$G$2:$G$301="False"))*order!$E$2:$E$301)} -> 1015.53
A9: nursingessay.us | B9: {=SUMPRODUCT((order!$B$2:$B$301=$A9)*1)-SUMPRODUCT((order!$B$2:$B$301=$A9)*(((order!$B$2:$B$301="essayhubpro.net")+(order!$B$2:$B$301="paperwise.co")+(order!$B$2:$B$301="editgenius.net"))*(order!$C$2:$C$301="US")*(order!$G$2:$G$301="False")))} -> 26 | C9: {=SUMPRODUCT((order!$B$2:$B$301=$A9)*order!$E$2:$E$301)-SUMPRODUCT((order!$B$2:$B$301=$A9)*(((order!$B$2:$B$301="essayhubpro.net")+(order!$B$2:$B$301="paperwise.co")+(order!$B$2:$B$301="editgenius.net"))*(order!$C$2:$C$301="US")*(order!$G$2:$G$301="False"))*order!$E$2:$E$301)} -> 2178.73 | E9: UK | F9: {=SUMPRODUCT((order!$C$2:$C$301=$E9)*1)-IF($E9="US",SUMPRODUCT((((order!$B$2:$B$301="essayhubpro.net")+(order!$B$2:$B$301="paperwise.co")+(order!$B$2:$B$301="editgenius.net"))*(order!$C$2:$C$301="US")*(order!$G$2:$G$301="False"))),0)} -> 53 | G9: {=SUMPRODUCT((order!$C$2:$C$301=$E9)*order!$E$2:$E$301)-IF($E9="US",SUMPRODUCT((((order!$B$2:$B$301="essayhubpro.net")+(order!$B$2:$B$301="paperwise.co")+(order!$B$2:$B$301="editgenius.net"))*(order!$C$2:$C$301="US")*(order!$G$2:$G$301="False"))*order!$E$2:$E$301),0)} -> 3872.71 | I9: 45811 | J9: {=SUMPRODUCT((order!$F$2:$F$301=I9)*order!$E$2:$E$301)-SUMPRODUCT((order!$F$2:$F$301=I9)*(((order!$B$2:$B$301="essayhubpro.net")+(order!$B$2:$B$301="paperwise.co")+(order!$B$2:$B$301="editgenius.net"))*(order!$C$2:$C$301="US")*(order!$G$2:$G$301="False"))*order!$E$2:$E$301)} -> 992.75
A10: essayhubpro.net | B10: {=SUMPRODUCT((order!$B$2:$B$301=$A10)*1)-SUMPRODUCT((order!$B$2:$B$301=$A10)*(((order!$B$2:$B$301="essayhubpro.net")+(order!$B$2:$B$301="paperwise.co")+(order!$B$2:$B$301="editgenius.net"))*(order!$C$2:$C$301="US")*(order!$G$2:$G$301="False")))} -> 26 | C10: {=SUMPRODUCT((order!$B$2:$B$301=$A10)*order!$E$2:$E$301)-SUMPRODUCT((order!$B$2:$B$301=$A10)*(((order!$B$2:$B$301="essayhubpro.net")+(order!$B$2:$B$301="paperwise.co")+(order!$B$2:$B$301="editgenius.net"))*(order!$C$2:$C$301="US")*(order!$G$2:$G$301="False"))*order!$E$2:$E$301)} -> 2097.54 | E10: AU | F10: {=SUMPRODUCT((order!$C$2:$C$301=$E10)*1)-IF($E10="US",SUMPRODUCT((((order!$B$2:$B$301="essayhubpro.net")+(order!$B$2:$B$301="paperwise.co")+(order!$B$2:$B$301="editgenius.net"))*(order!$C$2:$C$301="US")*(order!$G$2:$G$301="False"))),0)} -> 66 | G10: {=SUMPRODUCT((order!$C$2:$C$301=$E10)*order!$E$2:$E$301)-IF($E10="US",SUMPRODUCT((((order!$B$2:$B$301="essayhubpro.net")+(order!$B$2:$B$301="paperwise.co")+(order!$B$2:$B$301="editgenius.net"))*(order!$C$2:$C$301="US")*(order!$G$2:$G$301="False"))*order!$E$2:$E$301),0)} -> 5664.94 | I10: 45812 | J10: {=SUMPRODUCT((order!$F$2:$F$301=I10)*order!$E$2:$E$301)-SUMPRODUCT((order!$F$2:$F$301=I10)*(((order!$B$2:$B$301="essayhubpro.net")+(order!$B$2:$B$301="paperwise.co")+(order!$B$2:$B$301="editgenius.net"))*(order!$C$2:$C$301="US")*(order!$G$2:$G$301="False"))*order!$E$2:$E$301)} -> 762.09
A11: editgenius.net | B11: {=SUMPRODUCT((order!$B$2:$B$301=$A11)*1)-SUMPRODUCT((order!$B$2:$B$301=$A11)*(((order!$B$2:$B$301="essayhubpro.net")+(order!$B$2:$B$301="paperwise.co")+(order!$B$2:$B$301="editgenius.net"))*(order!$C$2:$C$301="US")*(order!$G$2:$G$301="False")))} -> 30 | C11: {=SUMPRODUCT((order!$B$2:$B$301=$A11)*order!$E$2:$E$301)-SUMPRODUCT((order!$B$2:$B$301=$A11)*(((order!$B$2:$B$301="essayhubpro.net")+(order!$B$2:$B$301="paperwise.co")+(order!$B$2:$B$301="editgenius.net"))*(order!$C$2:$C$301="US")*(order!$G$2:$G$301="False"))*order!$E$2:$E$301)} -> 2335.76 | E11: CA | F11: {=SUMPRODUCT((order!$C$2:$C$301=$E11)*1)-IF($E11="US",SUMPRODUCT((((order!$B$2:$B$301="essayhubpro.net")+(order!$B$2:$B$301="paperwise.co")+(order!$B$2:$B$301="editgenius.net"))*(order!$C$2:$C$301="US")*(order!$G$2:$G$301="False"))),0)} -> 64 | G11: {=SUMPRODUCT((order!$C$2:$C$301=$E11)*order!$E$2:$E$301)-IF($E11="US",SUMPRODUCT((((order!$B$2:$B$301="essayhubpro.net")+(order!$B$2:$B$301="paperwise.co")+(order!$B$2:$B$301="editgenius.net"))*(order!$C$2:$C$301="US")*(order!$G$2:$G$301="False"))*order!$E$2:$E$301),0)} -> 5247.05 | I11: 45813 | J11: {=SUMPRODUCT((order!$F$2:$F$301=I11)*order!$E$2:$E$301)-SUMPRODUCT((order!$F$2:$F$301=I11)*(((order!$B$2:$B$301="essayhubpro.net")+(order!$B$2:$B$301="paperwise.co")+(order!$B$2:$B$301="editgenius.net"))*(order!$C$2:$C$301="US")*(order!$G$2:$G$301="False"))*order!$E$2:$E$301)} -> 895.97
A12: leadacademica.co.uk | B12: {=SUMPRODUCT((order!$B$2:$B$301=$A12)*1)-SUMPRODUCT((order!$B$2:$B$301=$A12)*(((order!$B$2:$B$301="essayhubpro.net")+(order!$B$2:$B$301="paperwise.co")+(order!$B$2:$B$301="editgenius.net"))*(order!$C$2:$C$301="US")*(order!$G$2:$G$301="False")))} -> 37 | C12: {=SUMPRODUCT((order!$B$2:$B$301=$A12)*order!$E$2:$E$301)-SUMPRODUCT((order!$B$2:$B$301=$A12)*(((order!$B$2:$B$301="essayhubpro.net")+(order!$B$2:$B$301="paperwise.co")+(order!$B$2:$B$301="editgenius.net"))*(order!$C$2:$C$301="US")*(order!$G$2:$G$301="False"))*order!$E$2:$E$301)} -> 2717.08 | F12: =SUM(Table9[Кількість]) -> 292 | I12: 45814 | J12: {=SUMPRODUCT((order!$F$2:$F$301=I12)*order!$E$2:$E$301)-SUMPRODUCT((order!$F$2:$F$301=I12)*(((order!$B$2:$B$301="essayhubpro.net")+(order!$B$2:$B$301="paperwise.co")+(order!$B$2:$B$301="editgenius.net"))*(order!$C$2:$C$301="US")*(order!$G$2:$G$301="False"))*order!$E$2:$E$301)} -> 883.08
A13: slidecraft.com | B13: {=SUMPRODUCT((order!$B$2:$B$301=$A13)*1)-SUMPRODUCT((order!$B$2:$B$301=$A13)*(((order!$B$2:$B$301="essayhubpro.net")+(order!$B$2:$B$301="paperwise.co")+(order!$B$2:$B$301="editgenius.net"))*(order!$C$2:$C$301="US")*(order!$G$2:$G$301="False")))} -> 31 | C13: {=SUMPRODUCT((order!$B$2:$B$301=$A13)*order!$E$2:$E$301)-SUMPRODUCT((order!$B$2:$B$301=$A13)*(((order!$B$2:$B$301="essayhubpro.net")+(order!$B$2:$B$301="paperwise.co")+(order!$B$2:$B$301="editgenius.net"))*(order!$C$2:$C$301="US")*(order!$G$2:$G$301="False"))*order!$E$2:$E$301)} -> 2512.43 | I13: 45815 | J13: {=SUMPRODUCT((order!$F$2:$F$301=I13)*order!$E$2:$E$301)-SUMPRODUCT((order!$F$2:$F$301=I13)*(((order!$B$2:$B$301="essayhubpro.net")+(order!$B$2:$B$301="paperwise.co")+(order!$B$2:$B$301="editgenius.net"))*(order!$C$2:$C$301="US")*(order!$G$2:$G$301="False"))*order!$E$2:$E$301)} -> 554.94
A14: writemaster.co.uk | B14: {=SUMPRODUCT((order!$B$2:$B$301=$A14)*1)-SUMPRODUCT((order!$B$2:$B$301=$A14)*(((order!$B$2:$B$301="essayhubpro.net")+(order!$B$2:$B$301="paperwise.co")+(order!$B$2:$B$301="editgenius.net"))*(order!$C$2:$C$301="US")*(order!$G$2:$G$301="False")))} -> 36 | C14: {=SUMPRODUCT((order!$B$2:$B$301=$A14)*order!$E$2:$E$301)-SUMPRODUCT((order!$B$2:$B$301=$A14)*(((order!$B$2:$B$301="essayhubpro.net")+(order!$B$2:$B$301="paperwise.co")+(order!$B$2:$B$301="editgenius.net"))*(order!$C$2:$C$301="US")*(order!$G$2:$G$301="False"))*order!$E$2:$E$301)} -> 2684.6 | I14: 45816 | J14: {=SUMPRODUCT((order!$F$2:$F$301=I14)*order!$E$2:$E$301)-SUMPRODUCT((order!$F$2:$F$301=I14)*(((order!$B$2:$B$301="essayhubpro.net")+(order!$B$2:$B$301="paperwise.co")+(order!$B$2:$B$301="editgenius.net"))*(order!$C$2:$C$301="US")*(order!$G$2:$G$301="False"))*order!$E$2:$E$301)} -> 776.47
A15: progassignments.io | B15: {=SUMPRODUCT((order!$B$2:$B$301=$A15)*1)-SUMPRODUCT((order!$B$2:$B$301=$A15)*(((order!$B$2:$B$301="essayhubpro.net")+(order!$B$2:$B$301="paperwise.co")+(order!$B$2:$B$301="editgenius.net"))*(order!$C$2:$C$301="US")*(order!$G$2:$G$301="False")))} -> 31 | C15: {=SUMPRODUCT((order!$B$2:$B$301=$A15)*order!$E$2:$E$301)-SUMPRODUCT((order!$B$2:$B$301=$A15)*(((order!$B$2:$B$301="essayhubpro.net")+(order!$B$2:$B$301="paperwise.co")+(order!$B$2:$B$301="editgenius.net"))*(order!$C$2:$C$301="US")*(order!$G$2:$G$301="False"))*order!$E$2:$E$301)} -> 2344.34 | I15: 45817 | J15: {=SUMPRODUCT((order!$F$2:$F$301=I15)*order!$E$2:$E$301)-SUMPRODUCT((order!$F$2:$F$301=I15)*(((order!$B$2:$B$301="essayhubpro.net")+(order!$B$2:$B$301="paperwise.co")+(order!$B$2:$B$301="editgenius.net"))*(order!$C$2:$C$301="US")*(order!$G$2:$G$301="False"))*order!$E$2:$E$301)} -> 1000.73
I16: 45818 | J16: {=SUMPRODUCT((order!$F$2:$F$301=I16)*order!$E$2:$E$301)-SUMPRODUCT((order!$F$2:$F$301=I16)*(((order!$B$2:$B$301="essayhubpro.net")+(order!$B$2:$B$301="paperwise.co")+(order!$B$2:$B$301="editgenius.net"))*(order!$C$2:$C$301="US")*(order!$G$2:$G$301="False"))*order!$E$2:$E$301)} -> 764.28
I17: 45819 | J17: {=SUMPRODUCT((order!$F$2:$F$301=I17)*order!$E$2:$E$301)-SUMPRODUCT((order!$F$2:$F$301=I17)*(((order!$B$2:$B$301="essayhubpro.net")+(order!$B$2:$B$301="paperwise.co")+(order!$B$2:$B$301="editgenius.net"))*(order!$C$2:$C$301="US")*(order!$G$2:$G$301="False"))*order!$E$2:$E$301)} -> 966.2
A18: 2.3 Матриця суми продажів: сайт × регіон ($) | I18: 45820 | J18: {=SUMPRODUCT((order!$F$2:$F$301=I18)*order!$E$2:$E$301)-SUMPRODUCT((order!$F$2:$F$301=I18)*(((order!$B$2:$B$301="essayhubpro.net")+(order!$B$2:$B$301="paperwise.co")+(order!$B$2:$B$301="editgenius.net"))*(order!$C$2:$C$301="US")*(order!$G$2:$G$301="False"))*order!$E$2:$E$301)} -> 874.86
A19: Site | B19: US | C19: EU | D19: UK | E19: AU | F19: CA | G19: Разом | I19: 45821 | J19: {=SUMPRODUCT((order!$F$2:$F$301=I19)*order!$E$2:$E$301)-SUMPRODUCT((order!$F$2:$F$301=I19)*(((order!$B$2:$B$301="essayhubpro.net")+(order!$B$2:$B$301="paperwise.co")+(order!$B$2:$B$301="editgenius.net"))*(order!$C$2:$C$301="US")*(order!$G$2:$G$301="False"))*order!$E$2:$E$301)} -> 619.55
A20: paperwise.co | B20: {=SUMPRODUCT((order!$B$2:$B$301=$A20)*(order!$C$2:$C$301=B$19)*order!$E$2:$E$301)-IF(AND(B$19="US",OR($A20="essayhubpro.net",$A20="paperwise.co",$A20="editgenius.net")),SUMPRODUCT((order!$B$2:$B$301=$A20)*(order!$C$2:$C$301="US")*(order!$G$2:$G$301="False")*order!$E$2:$E$301),0)} -> 430.65 | C20: {=SUMPRODUCT((order!$B$2:$B$301=$A20)*(order!$C$2:$C$301=C$19)*order!$E$2:$E$301)-IF(AND(C$19="US",OR($A20="essayhubpro.net",$A20="paperwise.co",$A20="editgenius.net")),SUMPRODUCT((order!$B$2:$B$301=$A20)*(order!$C$2:$C$301="US")*(order!$G$2:$G$301="False")*order!$E$2:$E$301),0)} -> 461.41 | D20: {=SUMPRODUCT((order!$B$2:$B$301=$A20)*(order!$C$2:$C$301=D$19)*order!$E$2:$E$301)-IF(AND(D$19="US",OR($A20="essayhubpro.net",$A20="paperwise.co",$A20="editgenius.net")),SUMPRODUCT((order!$B$2:$B$301=$A20)*(order!$C$2:$C$301="US")*(order!$G$2:$G$301="False")*order!$E$2:$E$301),0)} -> 492.13 | E20: {=SUMPRODUCT((order!$B$2:$B$301=$A20)*(order!$C$2:$C$301=E$19)*order!$E$2:$E$301)-IF(AND(E$19="US",OR($A20="essayhubpro.net",$A20="paperwise.co",$A20="editgenius.net")),SUMPRODUCT((order!$B$2:$B$301=$A20)*(order!$C$2:$C$301="US")*(order!$G$2:$G$301="False")*order!$E$2:$E$301),0)} -> 774.64 | F20: {=SUMPRODUCT((order!$B$2:$B$301=$A20)*(order!$C$2:$C$301=F$19)*order!$E$2:$E$301)-IF(AND(F$19="US",OR($A20="essayhubpro.net",$A20="paperwise.co",$A20="editgenius.net")),SUMPRODUCT((order!$B$2:$B$301=$A20)*(order!$C$2:$C$301="US")*(order!$G$2:$G$301="False")*order!$E$2:$E$301),0)} -> 805.33 | G20: =SUM(B20:F20) -> 2964.16 | I20: 45822 | J20: {=SUMPRODUCT((order!$F$2:$F$301=I20)*order!$E$2:$E$301)-SUMPRODUCT((order!$F$2:$F$301=I20)*(((order!$B$2:$B$301="essayhubpro.net")+(order!$B$2:$B$301="paperwise.co")+(order!$B$2:$B$301="editgenius.net"))*(order!$C$2:$C$301="US")*(order!$G$2:$G$301="False"))*order!$E$2:$E$301)} -> 569.7
A21: typemaster.org | B21: {=SUMPRODUCT((order!$B$2:$B$301=$A21)*(order!$C$2:$C$301=B$19)*order!$E$2:$E$301)-IF(AND(B$19="US",OR($A21="essayhubpro.net",$A21="paperwise.co",$A21="editgenius.net")),SUMPRODUCT((order!$B$2:$B$301=$A21)*(order!$C$2:$C$301="US")*(order!$G$2:$G$301="False")*order!$E$2:$E$301),0)} -> 673.37 | C21: {=SUMPRODUCT((order!$B$2:$B$301=$A21)*(order!$C$2:$C$301=C$19)*order!$E$2:$E$301)-IF(AND(C$19="US",OR($A21="essayhubpro.net",$A21="paperwise.co",$A21="editgenius.net")),SUMPRODUCT((order!$B$2:$B$301=$A21)*(order!$C$2:$C$301="US")*(order!$G$2:$G$301="False")*order!$E$2:$E$301),0)} -> 503.07 | D21: {=SUMPRODUCT((order!$B$2:$B$301=$A21)*(order!$C$2:$C$301=D$19)*order!$E$2:$E$301)-IF(AND(D$19="US",OR($A21="essayhubpro.net",$A21="paperwise.co",$A21="editgenius.net")),SUMPRODUCT((order!$B$2:$B$301=$A21)*(order!$C$2:$C$301="US")*(order!$G$2:$G$301="False")*order!$E$2:$E$301),0)} -> 519.56 | E21: {=SUMPRODUCT((order!$B$2:$B$301=$A21)*(order!$C$2:$C$301=E$19)*order!$E$2:$E$301)-IF(AND(E$19="US",OR($A21="essayhubpro.net",$A21="paperwise.co",$A21="editgenius.net")),SUMPRODUCT((order!$B$2:$B$301=$A21)*(order!$C$2:$C$301="US")*(order!$G$2:$G$301="False")*order!$E$2:$E$301),0)} -> 881.05 | F21: {=SUMPRODUCT((order!$B$2:$B$301=$A21)*(order!$C$2:$C$301=F$19)*order!$E$2:$E$301)-IF(AND(F$19="US",OR($A21="essayhubpro.net",$A21="paperwise.co",$A21="editgenius.net")),SUMPRODUCT((order!$B$2:$B$301=$A21)*(order!$C$2:$C$301="US")*(order!$G$2:$G$301="False")*order!$E$2:$E$301),0)} -> 895.81 | G21: =SUM(B21:F21) -> 3472.86 | I21: 45823 | J21: {=SUMPRODUCT((order!$F$2:$F$301=I21)*order!$E$2:$E$301)-SUMPRODUCT((order!$F$2:$F$301=I21)*(((order!$B$2:$B$301="essayhubpro.net")+(order!$B$2:$B$301="paperwise.co")+(order!$B$2:$B$301="editgenius.net"))*(order!$C$2:$C$301="US")*(order!$G$2:$G$301="False"))*order!$E$2:$E$301)} -> 687.28
A22: nursingessay.us | B22: {=SUMPRODUCT((order!$B$2:$B$301=$A22)*(order!$C$2:$C$301=B$19)*order!$E$2:$E$301)-IF(AND(B$19="US",OR($A22="essayhubpro.net",$A22="paperwise.co",$A22="editgenius.net")),SUMPRODUCT((order!$B$2:$B$301=$A22)*(order!$C$2:$C$301="US")*(order!$G$2:$G$301="False")*order!$E$2:$E$301),0)} -> 468.97 | C22: {=SUMPRODUCT((order!$B$2:$B$301=$A22)*(order!$C$2:$C$301=C$19)*order!$E$2:$E$301)-IF(AND(C$19="US",OR($A22="essayhubpro.net",$A22="paperwise.co",$A22="editgenius.net")),SUMPRODUCT((order!$B$2:$B$301=$A22)*(order!$C$2:$C$301="US")*(order!$G$2:$G$301="False")*order!$E$2:$E$301),0)} -> 216.08 | D22: {=SUMPRODUCT((order!$B$2:$B$301=$A22)*(order!$C$2:$C$301=D$19)*order!$E$2:$E$301)-IF(AND(D$19="US",OR($A22="essayhubpro.net",$A22="paperwise.co",$A22="editgenius.net")),SUMPRODUCT((order!$B$2:$B$301=$A22)*(order!$C$2:$C$301="US")*(order!$G$2:$G$301="False")*order!$E$2:$E$301),0)} -> 519.91 | E22: {=SUMPRODUCT((order!$B$2:$B$301=$A22)*(order!$C$2:$C$301=E$19)*order!$E$2:$E$301)-IF(AND(E$19="US",OR($A22="essayhubpro.net",$A22="paperwise.co",$A22="editgenius.net")),SUMPRODUCT((order!$B$2:$B$301=$A22)*(order!$C$2:$C$301="US")*(order!$G$2:$G$301="False")*order!$E$2:$E$301),0)} -> 600.98 | F22: {=SUMPRODUCT((order!$B$2:$B$301=$A22)*(order!$C$2:$C$301=F$19)*order!$E$2:$E$301)-IF(AND(F$19="US",OR($A22="essayhubpro.net",$A22="paperwise.co",$A22="editgenius.net")),SUMPRODUCT((order!$B$2:$B$301=$A22)*(order!$C$2:$C$301="US")*(order!$G$2:$G$301="False")*order!$E$2:$E$301),0)} -> 372.79 | G22: =SUM(B22:F22) -> 2178.73 | I22: 45824 | J22: {=SUMPRODUCT((order!$F$2:$F$301=I22)*order!$E$2:$E$301)-SUMPRODUCT((order!$F$2:$F$301=I22)*(((order!$B$2:$B$301="essayhubpro.net")+(order!$B$2:$B$301="paperwise.co")+(order!$B$2:$B$301="editgenius.net"))*(order!$C$2:$C$301="US")*(order!$G$2:$G$301="False"))*order!$E$2:$E$301)} -> 786.23
A23: essayhubpro.net | B23: {=SUMPRODUCT((order!$B$2:$B$301=$A23)*(order!$C$2:$C$301=B$19)*order!$E$2:$E$301)-IF(AND(B$19="US",OR($A23="essayhubpro.net",$A23="paperwise.co",$A23="editgenius.net")),SUMPRODUCT((order!$B$2:$B$301=$A23)*(order!$C$2:$C$301="US")*(order!$G$2:$G$301="False")*order!$E$2:$E$301),0)} -> 166.56 | C23: {=SUMPRODUCT((order!$B$2:$B$301=$A23)*(order!$C$2:$C$301=C$19)*order!$E$2:$E$301)-IF(AND(C$19="US",OR($A23="essayhubpro.net",$A23="paperwise.co",$A23="editgenius.net")),SUMPRODUCT((order!$B$2:$B$301=$A23)*(order!$C$2:$C$301="US")*(order!$G$2:$G$301="False")*order!$E$2:$E$301),0)} -> 555.3 | D23: {=SUMPRODUCT((order!$B$2:$B$301=$A23)*(order!$C$2:$C$301=D$19)*order!$E$2:$E$301)-IF(AND(D$19="US",OR($A23="essayhubpro.net",$A23="paperwise.co",$A23="editgenius.net")),SUMPRODUCT((order!$B$2:$B$301=$A23)*(order!$C$2:$C$301="US")*(order!$G$2:$G$301="False")*order!$E$2:$E$301),0)} -> 175.29 | E23: {=SUMPRODUCT((order!$B$2:$B$301=$A23)*(order!$C$2:$C$301=E$19)*order!$E$2:$E$301)-IF(AND(E$19="US",OR($A23="essayhubpro.net",$A23="paperwise.co",$A23="editgenius.net")),SUMPRODUCT((order!$B$2:$B$301=$A23)*(order!$C$2:$C$301="US")*(order!$G$2:$G$301="False")*order!$E$2:$E$301),0)} -> 428.55 | F23: {=SUMPRODUCT((order!$B$2:$B$301=$A23)*(order!$C$2:$C$301=F$19)*order!$E$2:$E$301)-IF(AND(F$19="US",OR($A23="essayhubpro.net",$A23="paperwise.co",$A23="editgenius.net")),SUMPRODUCT((order!$B$2:$B$301=$A23)*(order!$C$2:$C$301="US")*(order!$G$2:$G$301="False")*order!$E$2:$E$301),0)} -> 771.84 | G23: =SUM(B23:F23) -> 2097.54 | I23: 45825 | J23: {=SUMPRODUCT((order!$F$2:$F$301=I23)*order!$E$2:$E$301)-SUMPRODUCT((order!$F$2:$F$301=I23)*(((order!$B$2:$B$301="essayhubpro.net")+(order!$B$2:$B$301="paperwise.co")+(order!$B$2:$B$301="editgenius.net"))*(order!$C$2:$C$301="US")*(order!$G$2:$G$301="False"))*order!$E$2:$E$301)} -> 409.27
A24: editgenius.net | B24: {=SUMPRODUCT((order!$B$2:$B$301=$A24)*(order!$C$2:$C$301=B$19)*order!$E$2:$E$301)-IF(AND(B$19="US",OR($A24="essayhubpro.net",$A24="paperwise.co",$A24="editgenius.net")),SUMPRODUCT((order!$B$2:$B$301=$A24)*(order!$C$2:$C$301="US")*(order!$G$2:$G$301="False")*order!$E$2:$E$301),0)} -> 146.22 | C24: {=SUMPRODUCT((order!$B$2:$B$301=$A24)*(order!$C$2:$C$301=C$19)*order!$E$2:$E$301)-IF(AND(C$19="US",OR($A24="essayhubpro.net",$A24="paperwise.co",$A24="editgenius.net")),SUMPRODUCT((order!$B$2:$B$301=$A24)*(order!$C$2:$C$301="US")*(order!$G$2:$G$301="False")*order!$E$2:$E$301),0)} -> 663.98 | D24: {=SUMPRODUCT((order!$B$2:$B$301=$A24)*(order!$C$2:$C$301=D$19)*order!$E$2:$E$301)-IF(AND(D$19="US",OR($A24="essayhubpro.net",$A24="paperwise.co",$A24="editgenius.net")),SUMPRODUCT((order!$B$2:$B$301=$A24)*(order!$C$2:$C$301="US")*(order!$G$2:$G$301="False")*order!$E$2:$E$301),0)} -> 197.41 | E24: {=SUMPRODUCT((order!$B$2:$B$301=$A24)*(order!$C$2:$C$301=E$19)*order!$E$2:$E$301)-IF(AND(E$19="US",OR($A24="essayhubpro.net",$A24="paperwise.co",$A24="editgenius.net")),SUMPRODUCT((order!$B$2:$B$301=$A24)*(order!$C$2:$C$301="US")*(order!$G$2:$G$301="False")*order!$E$2:$E$301),0)} -> 548.28 | F24: {=SUMPRODUCT((order!$B$2:$B$301=$A24)*(order!$C$2:$C$301=F$19)*order!$E$2:$E$301)-IF(AND(F$19="US",OR($A24="essayhubpro.net",$A24="paperwise.co",$A24="editgenius.net")),SUMPRODUCT((order!$B$2:$B$301=$A24)*(order!$C$2:$C$301="US")*(order!$G$2:$G$301="False")*order!$E$2:$E$301),0)} -> 779.87 | G24: =SUM(B24:F24) -> 2335.76 | I24: 45826 | J24: {=SUMPRODUCT((order!$F$2:$F$301=I24)*order!$E$2:$E$301)-SUMPRODUCT((order!$F$2:$F$301=I24)*(((order!$B$2:$B$301="essayhubpro.net")+(order!$B$2:$B$301="paperwise.co")+(order!$B$2:$B$301="editgenius.net"))*(order!$C$2:$C$301="US")*(order!$G$2:$G$301="False"))*order!$E$2:$E$301)} -> 574.09
A25: leadacademica.co.uk | B25: {=SUMPRODUCT((order!$B$2:$B$301=$A25)*(order!$C$2:$C$301=B$19)*order!$E$2:$E$301)-IF(AND(B$19="US",OR($A25="essayhubpro.net",$A25="paperwise.co",$A25="editgenius.net")),SUMPRODUCT((order!$B$2:$B$301=$A25)*(order!$C$2:$C$301="US")*(order!$G$2:$G$301="False")*order!$E$2:$E$301),0)} -> 598.64 | C25: {=SUMPRODUCT((order!$B$2:$B$301=$A25)*(order!$C$2:$C$301=C$19)*order!$E$2:$E$301)-IF(AND(C$19="US",OR($A25="essayhubpro.net",$A25="paperwise.co",$A25="editgenius.net")),SUMPRODUCT((order!$B$2:$B$301=$A25)*(order!$C$2:$C$301="US")*(order!$G$2:$G$301="False")*order!$E$2:$E$301),0)} -> 551.88 | D25: {=SUMPRODUCT((order!$B$2:$B$301=$A25)*(order!$C$2:$C$301=D$19)*order!$E$2:$E$301)-IF(AND(D$19="US",OR($A25="essayhubpro.net",$A25="paperwise.co",$A25="editgenius.net")),SUMPRODUCT((order!$B$2:$B$301=$A25)*(order!$C$2:$C$301="US")*(order!$G$2:$G$301="False")*order!$E$2:$E$301),0)} -> 560.69 | E25: {=SUMPRODUCT((order!$B$2:$B$301=$A25)*(order!$C$2:$C$301=E$19)*order!$E$2:$E$301)-IF(AND(E$19="US",OR($A25="essayhubpro.net",$A25="paperwise.co",$A25="editgenius.net")),SUMPRODUCT((order!$B$2:$B$301=$A25)*(order!$C$2:$C$301="US")*(order!$G$2:$G$301="False")*order!$E$2:$E$301),0)} -> 647.46 | F25: {=SUMPRODUCT((order!$B$2:$B$301=$A25)*(order!$C$2:$C$301=F$19)*order!$E$2:$E$301)-IF(AND(F$19="US",OR($A25="essayhubpro.net",$A25="paperwise.co",$A25="editgenius.net")),SUMPRODUCT((order!$B$2:$B$301=$A25)*(order!$C$2:$C$301="US")*(order!$G$2:$G$301="False")*order!$E$2:$E$301),0)} -> 358.41 | G25: =SUM(B25:F25) -> 2717.08 | I25: 45827 | J25: {=SUMPRODUCT((order!$F$2:$F$301=I25)*order!$E$2:$E$301)-SUMPRODUCT((order!$F$2:$F$301=I25)*(((order!$B$2:$B$301="essayhubpro.net")+(order!$B$2:$B$301="paperwise.co")+(order!$B$2:$B$301="editgenius.net"))*(order!$C$2:$C$301="US")*(order!$G$2:$G$301="False"))*order!$E$2:$E$301)} -> 507.11
A26: slidecraft.com | B26: {=SUMPRODUCT((order!$B$2:$B$301=$A26)*(order!$C$2:$C$301=B$19)*order!$E$2:$E$301)-IF(AND(B$19="US",OR($A26="essayhubpro.net",$A26="paperwise.co",$A26="editgenius.net")),SUMPRODUCT((order!$B$2:$B$301=$A26)*(order!$C$2:$C$301="US")*(order!$G$2:$G$301="False")*order!$E$2:$E$301),0)} -> 578.05 | C26: {=SUMPRODUCT((order!$B$2:$B$301=$A26)*(order!$C$2:$C$301=C$19)*order!$E$2:$E$301)-IF(AND(C$19="US",OR($A26="essayhubpro.net",$A26="paperwise.co",$A26="editgenius.net")),SUMPRODUCT((order!$B$2:$B$301=$A26)*(order!$C$2:$C$301="US")*(order!$G$2:$G$301="False")*order!$E$2:$E$301),0)} -> 593.35 | D26: {=SUMPRODUCT((order!$B$2:$B$301=$A26)*(order!$C$2:$C$301=D$19)*order!$E$2:$E$301)-IF(AND(D$19="US",OR($A26="essayhubpro.net",$A26="paperwise.co",$A26="editgenius.net")),SUMPRODUCT((order!$B$2:$B$301=$A26)*(order!$C$2:$C$301="US")*(order!$G$2:$G$301="False")*order!$E$2:$E$301),0)} -> 309.92 | E26: {=SUMPRODUCT((order!$B$2:$B$301=$A26)*(order!$C$2:$C$301=E$19)*order!$E$2:$E$301)-IF(AND(E$19="US",OR($A26="essayhubpro.net",$A26="paperwise.co",$A26="editgenius.net")),SUMPRODUCT((order!$B$2:$B$301=$A26)*(order!$C$2:$C$301="US")*(order!$G$2:$G$301="False")*order!$E$2:$E$301),0)} -> 741.25 | F26: {=SUMPRODUCT((order!$B$2:$B$301=$A26)*(order!$C$2:$C$301=F$19)*order!$E$2:$E$301)-IF(AND(F$19="US",OR($A26="essayhubpro.net",$A26="paperwise.co",$A26="editgenius.net")),SUMPRODUCT((order!$B$2:$B$301=$A26)*(order!$C$2:$C$301="US")*(order!$G$2:$G$301="False")*order!$E$2:$E$301),0)} -> 289.86 | G26: =SUM(B26:F26) -> 2512.43 | I26: 45828 | J26: {=SUMPRODUCT((order!$F$2:$F$301=I26)*order!$E$2:$E$301)-SUMPRODUCT((order!$F$2:$F$301=I26)*(((order!$B$2:$B$301="essayhubpro.net")+(order!$B$2:$B$301="paperwise.co")+(order!$B$2:$B$301="editgenius.net"))*(order!$C$2:$C$301="US")*(order!$G$2:$G$301="False"))*order!$E$2:$E$301)} -> 1232.31
A27: writemaster.co.uk | B27: {=SUMPRODUCT((order!$B$2:$B$301=$A27)*(order!$C$2:$C$301=B$19)*order!$E$2:$E$301)-IF(AND(B$19="US",OR($A27="essayhubpro.net",$A27="paperwise.co",$A27="editgenius.net")),SUMPRODUCT((order!$B$2:$B$301=$A27)*(order!$C$2:$C$301="US")*(order!$G$2:$G$301="False")*order!$E$2:$E$301),0)} -> 598.13 | C27: {=SUMPRODUCT((order!$B$2:$B$301=$A27)*(order!$C$2:$C$301=C$19)*order!$E$2:$E$301)-IF(AND(C$19="US",OR($A27="essayhubpro.net",$A27="paperwise.co",$A27="editgenius.net")),SUMPRODUCT((order!$B$2:$B$301=$A27)*(order!$C$2:$C$301="US")*(order!$G$2:$G$301="False")*order!$E$2:$E$301),0)} -> 661.22 | D27: {=SUMPRODUCT((order!$B$2:$B$301=$A27)*(order!$C$2:$C$301=D$19)*order!$E$2:$E$301)-IF(AND(D$19="US",OR($A27="essayhubpro.net",$A27="paperwise.co",$A27="editgenius.net")),SUMPRODUCT((order!$B$2:$B$301=$A27)*(order!$C$2:$C$301="US")*(order!$G$2:$G$301="False")*order!$E$2:$E$301),0)} -> 330.56 | E27: {=SUMPRODUCT((order!$B$2:$B$301=$A27)*(order!$C$2:$C$301=E$19)*order!$E$2:$E$301)-IF(AND(E$19="US",OR($A27="essayhubpro.net",$A27="paperwise.co",$A27="editgenius.net")),SUMPRODUCT((order!$B$2:$B$301=$A27)*(order!$C$2:$C$301="US")*(order!$G$2:$G$301="False")*order!$E$2:$E$301),0)} -> 495.06 | F27: {=SUMPRODUCT((order!$B$2:$B$301=$A27)*(order!$C$2:$C$301=F$19)*order!$E$2:$E$301)-IF(AND(F$19="US",OR($A27="essayhubpro.net",$A27="paperwise.co",$A27="editgenius.net")),SUMPRODUCT((order!$B$2:$B$301=$A27)*(order!$C$2:$C$301="US")*(order!$G$2:$G$301="False")*order!$E$2:$E$301),0)} -> 599.63 | G27: =SUM(B27:F27) -> 2684.6 | I27: 45829 | J27: {=SUMPRODUCT((order!$F$2:$F$301=I27)*order!$E$2:$E$301)-SUMPRODUCT((order!$F$2:$F$301=I27)*(((order!$B$2:$B$301="essayhubpro.net")+(order!$B$2:$B$301="paperwise.co")+(order!$B$2:$B$301="editgenius.net"))*(order!$C$2:$C$301="US")*(order!$G$2:$G$301="False"))*order!$E$2:$E$301)} -> 728.45
A28: progassignments.io | B28: {=SUMPRODUCT((order!$B$2:$B$301=$A28)*(order!$C$2:$C$301=B$19)*order!$E$2:$E$301)-IF(AND(B$19="US",OR($A28="essayhubpro.net",$A28="paperwise.co",$A28="editgenius.net")),SUMPRODUCT((order!$B$2:$B$301=$A28)*(order!$C$2:$C$301="US")*(order!$G$2:$G$301="False")*order!$E$2:$E$301),0)} -> 312.73 | C28: {=SUMPRODUCT((order!$B$2:$B$301=$A28)*(order!$C$2:$C$301=C$19)*order!$E$2:$E$301)-IF(AND(C$19="US",OR($A28="essayhubpro.net",$A28="paperwise.co",$A28="editgenius.net")),SUMPRODUCT((order!$B$2:$B$301=$A28)*(order!$C$2:$C$301="US")*(order!$G$2:$G$301="False")*order!$E$2:$E$301),0)} -> 343.19 | D28: {=SUMPRODUCT((order!$B$2:$B$301=$A28)*(order!$C$2:$C$301=D$19)*order!$E$2:$E$301)-IF(AND(D$19="US",OR($A28="essayhubpro.net",$A28="paperwise.co",$A28="editgenius.net")),SUMPRODUCT((order!$B$2:$B$301=$A28)*(order!$C$2:$C$301="US")*(order!$G$2:$G$301="False")*order!$E$2:$E$301),0)} -> 767.24 | E28: {=SUMPRODUCT((order!$B$2:$B$301=$A28)*(order!$C$2:$C$301=E$19)*order!$E$2:$E$301)-IF(AND(E$19="US",OR($A28="essayhubpro.net",$A28="paperwise.co",$A28="editgenius.net")),SUMPRODUCT((order!$B$2:$B$301=$A28)*(order!$C$2:$C$301="US")*(order!$G$2:$G$301="False")*order!$E$2:$E$301),0)} -> 547.67 | F28: {=SUMPRODUCT((order!$B$2:$B$301=$A28)*(order!$C$2:$C$301=F$19)*order!$E$2:$E$301)-IF(AND(F$19="US",OR($A28="essayhubpro.net",$A28="paperwise.co",$A28="editgenius.net")),SUMPRODUCT((order!$B$2:$B$301=$A28)*(order!$C$2:$C$301="US")*(order!$G$2:$G$301="False")*order!$E$2:$E$301),0)} -> 373.51 | G28: =SUM(B28:F28) -> 2344.34 | I28: 45830 | J28: {=SUMPRODUCT((order!$F$2:$F$301=I28)*order!$E$2:$E$301)-SUMPRODUCT((order!$F$2:$F$301=I28)*(((order!$B$2:$B$301="essayhubpro.net")+(order!$B$2:$B$301="paperwise.co")+(order!$B$2:$B$301="editgenius.net"))*(order!$C$2:$C$301="US")*(order!$G$2:$G$301="False"))*order!$E$2:$E$301)} -> 746.48
I29: 45831 | J29: {=SUMPRODUCT((order!$F$2:$F$301=I29)*order!$E$2:$E$301)-SUMPRODUCT((order!$F$2:$F$301=I29)*(((order!$B$2:$B$301="essayhubpro.net")+(order!$B$2:$B$301="paperwise.co")+(order!$B$2:$B$301="editgenius.net"))*(order!$C$2:$C$301="US")*(order!$G$2:$G$301="False"))*order!$E$2:$E$301)} -> 902.06
I30: 45832 | J30: {=SUMPRODUCT((order!$F$2:$F$301=I30)*order!$E$2:$E$301)-SUMPRODUCT((order!$F$2:$F$301=I30)*(((order!$B$2:$B$301="essayhubpro.net")+(order!$B$2:$B$301="paperwise.co")+(order!$B$2:$B$301="editgenius.net"))*(order!$C$2:$C$301="US")*(order!$G$2:$G$301="False"))*order!$E$2:$E$301)} -> 643.53
I31: 45833 | J31: {=SUMPRODUCT((order!$F$2:$F$301=I31)*order!$E$2:$E$301)-SUMPRODUCT((order!$F$2:$F$301=I31)*(((order!$B$2:$B$301="essayhubpro.net")+(order!$B$2:$B$301="paperwise.co")+(order!$B$2:$B$301="editgenius.net"))*(order!$C$2:$C$301="US")*(order!$G$2:$G$301="False"))*order!$E$2:$E$301)} -> 1087.12
I32: 45834 | J32: {=SUMPRODUCT((order!$F$2:$F$301=I32)*order!$E$2:$E$301)-SUMPRODUCT((order!$F$2:$F$301=I32)*(((order!$B$2:$B$301="essayhubpro.net")+(order!$B$2:$B$301="paperwise.co")+(order!$B$2:$B$301="editgenius.net"))*(order!$C$2:$C$301="US")*(order!$G$2:$G$301="False"))*order!$E$2:$E$301)} -> 925.62
I33: 45835 | J33: {=SUMPRODUCT((order!$F$2:$F$301=I33)*order!$E$2:$E$301)-SUMPRODUCT((order!$F$2:$F$301=I33)*(((order!$B$2:$B$301="essayhubpro.net")+(order!$B$2:$B$301="paperwise.co")+(order!$B$2:$B$301="editgenius.net"))*(order!$C$2:$C$301="US")*(order!$G$2:$G$301="False"))*order!$E$2:$E$301)} -> 321.66
I34: 45836 | J34: {=SUMPRODUCT((order!$F$2:$F$301=I34)*order!$E$2:$E$301)-SUMPRODUCT((order!$F$2:$F$301=I34)*(((order!$B$2:$B$301="essayhubpro.net")+(order!$B$2:$B$301="paperwise.co")+(order!$B$2:$B$301="editgenius.net"))*(order!$C$2:$C$301="US")*(order!$G$2:$G$301="False"))*order!$E$2:$E$301)} -> 1082.39
I35: 45837 | J35: {=SUMPRODUCT((order!$F$2:$F$301=I35)*order!$E$2:$E$301)-SUMPRODUCT((order!$F$2:$F$301=I35)*(((order!$B$2:$B$301="essayhubpro.net")+(order!$B$2:$B$301="paperwise.co")+(order!$B$2:$B$301="editgenius.net"))*(order!$C$2:$C$301="US")*(order!$G$2:$G$301="False"))*order!$E$2:$E$301)} -> 571.88
I36: 45838 | J36: {=SUMPRODUCT((order!$F$2:$F$301=I36)*order!$E$2:$E$301)-SUMPRODUCT((order!$F$2:$F$301=I36)*(((order!$B$2:$B$301="essayhubpro.net")+(order!$B$2:$B$301="paperwise.co")+(order!$B$2:$B$301="editgenius.net"))*(order!$C$2:$C$301="US")*(order!$G$2:$G$301="False"))*order!$E$2:$E$301)} -> 714.14
I37: Total | J37: =SUM(J7:J36) -> 23307.5

Sheet task_3
A1: 3. Аналіз подій сайтів: conversion та поведінкова воронка
A3: 3.1 Кількість подій conversion по сайтах (від найбільшої)
A4: Site | B4: conversion | C4: cta_click | D4: form_submit | E4: checkout_initiate | F4: Всього подій | G4: Conv. Rate | H4: Conv. rate 2
A5: progassignments.io | B5: =COUNTIFS(site_event_log!$A:$A,$A5,site_event_log!$B:$B,B$4) -> 19 | C5: =COUNTIFS(site_event_log!$A:$A,$A5,site_event_log!$B:$B,C$4) -> 15 | D5: =COUNTIFS(site_event_log!$A:$A,$A5,site_event_log!$B:$B,D$4) -> 9 | E5: =COUNTIFS(site_event_log!$A:$A,$A5,site_event_log!$B:$B,E$4) -> 13 | F5: =SUM(B5:E5) -> 56 | G5: =IF(C5=0,0,B5/C5) -> 1.2666667 | H5: =IFERROR(B5/SUMIF(traffic_sources!A:A,A5,traffic_sources!C:C),0) -> 0.0050211416
